<?xml version='1.0' encoding='utf-8'?>
<sdf version="1.6">
  <model name="cerberus_anymal_c_sensor_config_1">
    <link name="base">
      <pose>0 0 0 0 0 0</pose>
      <inertial>
        <pose>-0.0143195 -0.0001053 0.0059904 0 0 0</pose>
        <mass>29.23832</mass>
        <inertia>
          <ixx>0.236867</ixx>
          <ixy>0.00846724</ixy>
          <ixz>0.0854364</ixz>
          <iyy>2.06849</iyy>
          <iyz>-0.000253399</iyz>
          <izz>2.09006</izz>
        </inertia>
      </inertial>
      <collision name="base_collision">
        <pose>0 0 0 0 0 0</pose>
        <geometry>
          <box>
            <size>0.377 0.091 0.117</size>
          </box>
        </geometry>
      </collision>
      <collision name="base_collision_1">
        <pose>0.141375 0.0455 0 0 1.5708 0</pose>
        <geometry>
          <cylinder>
            <length>0.09425</length>
            <radius>0.0585</radius>
          </cylinder>
        </geometry>
      </collision>
      <collision name="base_collision_2">
        <pose>-0.141375 0.0455 0 0 1.5708 0</pose>
        <geometry>
          <cylinder>
            <length>0.09425</length>
            <radius>0.0585</radius>
          </cylinder>
        </geometry>
      </collision>
      <collision name="base_collision_3">
        <pose>0.141375 -0.0455 0 0 1.5708 0</pose>
        <geometry>
          <cylinder>
            <length>0.09425</length>
            <radius>0.0585</radius>
          </cylinder>
        </geometry>
      </collision>
      <collision name="base_collision_4">
        <pose>-0.141375 -0.0455 0 0 1.5708 0</pose>
        <geometry>
          <cylinder>
            <length>0.09425</length>
            <radius>0.0585</radius>
          </cylinder>
        </geometry>
      </collision>
      <collision name="base_fixed_joint_lump__alphasense_mesh_collision_5">
        <pose>-0.2272387 0 0.15275 0 0 0</pose>
        <geometry>
          <box>
            <size>0.0832 0.10725 0.0637</size>
          </box>
        </geometry>
      </collision>
      <collision name="base_fixed_joint_lump__bpearl_front_collision_6">
        <pose>0.32600555 0 -0.00653445 -2.85388 -0.54666 -0.517507</pose>
        <geometry>
          <box>
            <size>0.065 0.065 0.0715</size>
          </box>
        </geometry>
      </collision>
      <collision name="base_fixed_joint_lump__bpearl_front_protection_bars_collision_collision_7">
        <pose>0.2852694 0 -0.050349 3.14159 0.893609 3.14159</pose>
        <geometry>
          <box>
            <size>0.0195 0.0117 0.065</size>
          </box>
        </geometry>
      </collision>
      <collision name="base_fixed_joint_lump__bpearl_front_protection_bars_collision_collision_8">
        <pose>0.329524 0 -0.0772876 1e-06 1.52542 1e-06</pose>
        <geometry>
          <box>
            <size>0.0195 0.01105 0.0442</size>
          </box>
        </geometry>
      </collision>
      <collision name="base_fixed_joint_lump__bpearl_front_protection_bars_collision_collision_9">
        <pose>0.3639922 -0.0448136 0.00477295 -2.68278 -0.125844 -0.83529</pose>
        <geometry>
          <box>
            <size>0.0195 0.00325 0.065</size>
          </box>
        </geometry>
      </collision>
      <collision name="base_fixed_joint_lump__bpearl_front_protection_bars_collision_collision_10">
        <pose>0.3802565 -0.02888015 -0.04176445 -2.61177 0.516776 -0.491692</pose>
        <geometry>
          <box>
            <size>0.0195 0.0104 0.0442</size>
          </box>
        </geometry>
      </collision>
      <collision name="base_fixed_joint_lump__bpearl_front_protection_bars_collision_collision_11">
        <pose>0.3620292 0.04672005 0.0033982 2.66301 -0.103127 0.880443</pose>
        <geometry>
          <box>
            <size>0.0195 0.00325 0.065</size>
          </box>
        </geometry>
      </collision>
      <collision name="base_fixed_joint_lump__bpearl_front_protection_bars_collision_collision_12">
        <pose>0.37899095 0.03010865 -0.0426504 2.58142 0.531321 0.5194</pose>
        <geometry>
          <box>
            <size>0.0195 0.0104 0.0442</size>
          </box>
        </geometry>
      </collision>
      <collision name="base_fixed_joint_lump__bpearl_rear_collision_13">
        <pose>-0.32600555 0 -0.00653445 -2.85388 -0.54666 2.62409</pose>
        <geometry>
          <box>
            <size>0.065 0.065 0.0715</size>
          </box>
        </geometry>
      </collision>
      <collision name="base_fixed_joint_lump__bpearl_rear_protection_bars_collision_collision_14">
        <pose>-0.2852694 0 -0.050349 3.14159 0.893609 0</pose>
        <geometry>
          <box>
            <size>0.0195 0.0117 0.065</size>
          </box>
        </geometry>
      </collision>
      <collision name="base_fixed_joint_lump__bpearl_rear_protection_bars_collision_collision_15">
        <pose>-0.329524 0 -0.0772876 1e-06 1.52542 -3.14159</pose>
        <geometry>
          <box>
            <size>0.0195 0.01105 0.0442</size>
          </box>
        </geometry>
      </collision>
      <collision name="base_fixed_joint_lump__bpearl_rear_protection_bars_collision_collision_16">
        <pose>-0.3676608 0.04063735 0.00734175 -2.72553 -0.168473 2.39838</pose>
        <geometry>
          <box>
            <size>0.0195 0.00325 0.065</size>
          </box>
        </geometry>
      </collision>
      <collision name="base_fixed_joint_lump__bpearl_rear_protection_bars_collision_collision_17">
        <pose>-0.38262055 0.0261885 -0.0401089 -2.67308 0.489917 2.70612</pose>
        <geometry>
          <box>
            <size>0.0195 0.0104 0.0442</size>
          </box>
        </geometry>
      </collision>
      <collision name="base_fixed_joint_lump__bpearl_rear_protection_bars_collision_collision_18">
        <pose>-0.35998625 -0.04849845 0.0019682 2.64433 -0.079552 -2.21655</pose>
        <geometry>
          <box>
            <size>0.0195 0.00325 0.065</size>
          </box>
        </geometry>
      </collision>
      <collision name="base_fixed_joint_lump__bpearl_rear_protection_bars_collision_collision_19">
        <pose>-0.3776747 -0.0312546 -0.0435721 2.55129 0.546584 -2.59477</pose>
        <geometry>
          <box>
            <size>0.0195 0.0104 0.0442</size>
          </box>
        </geometry>
      </collision>
      <collision name="base_fixed_joint_lump__perception_head_cage_collision_20">
        <pose>-0.23137205 0 0.10491 0 0 0</pose>
        <geometry>
          <box>
            <size>0.0919815 0.140036 0.11492</size>
          </box>
        </geometry>
      </collision>
      <collision name="base_fixed_joint_lump__imu_link_collision_21">
        <pose>0.16172 0.0054275 0.033332 0 0 1.5708</pose>
        <geometry>
          <box>
            <size>0.0156 0.0156 0.0065</size>
          </box>
        </geometry>
      </collision>
      <visual name="base_visual">
        <pose>0 0 0 0 0 0</pose>
        <geometry>
          <mesh>
            <scale>0.65 0.65 0.65</scale>
            <uri>meshes/base.dae</uri>
          </mesh>
        </geometry>
      </visual>
      <visual name="base_fixed_joint_lump__LF_HAA_visual_1">
        <pose>0.194935 0.0676 0 2.61799 0 0</pose>
        <geometry>
          <mesh>
            <scale>0.65 0.65 0.65</scale>
            <uri>meshes/drive.dae</uri>
          </mesh>
        </geometry>
      </visual>
      <visual name="base_fixed_joint_lump__LH_HAA_visual_2">
        <pose>-0.194935 0.0676 0 -2.61799 0 3.14159</pose>
        <geometry>
          <mesh>
            <scale>0.65 0.65 0.65</scale>
            <uri>meshes/drive.dae</uri>
          </mesh>
        </geometry>
      </visual>
      <visual name="base_fixed_joint_lump__RF_HAA_visual_3">
        <pose>0.194935 -0.0676 0 -2.61799 0 0</pose>
        <geometry>
          <mesh>
            <scale>0.65 0.65 0.65</scale>
            <uri>meshes/drive.dae</uri>
          </mesh>
        </geometry>
      </visual>
      <visual name="base_fixed_joint_lump__RH_HAA_visual_4">
        <pose>-0.194935 -0.0676 0 2.61799 0 3.14159</pose>
        <geometry>
          <mesh>
            <scale>0.65 0.65 0.65</scale>
            <uri>meshes/drive.dae</uri>
          </mesh>
        </geometry>
      </visual>
      <visual name="base_fixed_joint_lump__battery_visual_5">
        <pose>0 0 0 0 0 0</pose>
        <geometry>
          <mesh>
            <scale>0.65 0.65 0.65</scale>
            <uri>meshes/battery.dae</uri>
          </mesh>
        </geometry>
      </visual>
      <visual name="base_fixed_joint_lump__bottom_shell_visual_6">
        <pose>0 0 0 0 0 0</pose>
        <geometry>
          <mesh>
            <scale>0.65 0.65 0.65</scale>
            <uri>meshes/bottom_shell.dae</uri>
          </mesh>
        </geometry>
      </visual>
      <visual name="base_fixed_joint_lump__handle_visual_7">
        <pose>0 0 0 0 0 0</pose>
        <geometry>
          <mesh>
            <scale>0.65 0.65 0.65</scale>
            <uri>meshes/handle.dae</uri>
          </mesh>
        </geometry>
      </visual>
      <visual name="base_fixed_joint_lump__hatch_visual_8">
        <pose>0.0754 0 0.04745 0 0 0</pose>
        <geometry>
          <mesh>
            <scale>0.65 0.65 0.65</scale>
            <uri>meshes/hatch.dae</uri>
          </mesh>
        </geometry>
      </visual>
      <visual name="base_fixed_joint_lump__remote_visual_9">
        <pose>0 0 0 0 0 0</pose>
        <geometry>
          <mesh>
            <scale>0.65 0.65 0.65</scale>
            <uri>meshes/remote.dae</uri>
          </mesh>
        </geometry>
      </visual>
      <visual name="base_fixed_joint_lump__alphasense_mesh_visual_10">
        <pose>-0.2366 0 0 0 0 0</pose>
        <geometry>
          <mesh>
            <scale>0.00065 0.00065 0.00065</scale>
            <uri>meshes/alphasense.stl</uri>
          </mesh>
        </geometry>
        <material>
          <ambient>0.5 0.5 0.5 1</ambient>
          <diffuse>0.5 0.5 0.5 1</diffuse>
          <specular>0.5 0.5 0.5 1</specular>
        </material>
      </visual>
      <visual name="base_fixed_joint_lump__bpearl_front_visual_11">
        <pose>0.3055 0 0.02275 -2.85388 -0.54666 -0.517507</pose>
        <geometry>
          <mesh>
            <scale>0.00065 0.00065 0.00065</scale>
            <uri>meshes/rslidar_bpearl.stl</uri>
          </mesh>
        </geometry>
        <material>
          <ambient>0.5 0.5 0.5 1</ambient>
          <diffuse>0.5 0.5 0.5 1</diffuse>
          <specular>0.5 0.5 0.5 1</specular>
        </material>
      </visual>
      <visual name="base_fixed_joint_lump__bpearl_front_protection_bars_visual_12">
        <pose>0.26942175 0 0 0 0 -3.14159</pose>
        <geometry>
          <mesh>
            <scale>0.00065 0.00065 0.00065</scale>
            <uri>meshes/bpearl_protection_bars.stl</uri>
          </mesh>
        </geometry>
        <material>
          <ambient>0.5 0.5 0.5 1</ambient>
          <diffuse>0.5 0.5 0.5 1</diffuse>
          <specular>0.5 0.5 0.5 1</specular>
        </material>
      </visual>
      <visual name="base_fixed_joint_lump__bpearl_rear_visual_13">
        <pose>-0.3055 0 0.02275 -2.85388 -0.54666 2.62409</pose>
        <geometry>
          <mesh>
            <scale>0.00065 0.00065 0.00065</scale>
            <uri>meshes/rslidar_bpearl.stl</uri>
          </mesh>
        </geometry>
        <material>
          <ambient>0.5 0.5 0.5 1</ambient>
          <diffuse>0.5 0.5 0.5 1</diffuse>
          <specular>0.5 0.5 0.5 1</specular>
        </material>
      </visual>
      <visual name="base_fixed_joint_lump__bpearl_rear_protection_bars_visual_14">
        <pose>-0.26942175 0 0 0 0 0</pose>
        <geometry>
          <mesh>
            <scale>0.00065 0.00065 0.00065</scale>
            <uri>meshes/bpearl_protection_bars.stl</uri>
          </mesh>
        </geometry>
        <material>
          <ambient>0.5 0.5 0.5 1</ambient>
          <diffuse>0.5 0.5 0.5 1</diffuse>
          <specular>0.5 0.5 0.5 1</specular>
        </material>
      </visual>
      <visual name="base_fixed_joint_lump__perception_head_cage_visual_15">
        <pose>-0.2366 0 0 0 0 0</pose>
        <geometry>
          <mesh>
            <scale>0.00065 0.00065 0.00065</scale>
            <uri>meshes/perception_head.stl</uri>
          </mesh>
        </geometry>
        <material>
          <ambient>0.5 0.5 0.5 1</ambient>
          <diffuse>0.5 0.5 0.5 1</diffuse>
          <specular>0.5 0.5 0.5 1</specular>
        </material>
      </visual>
      <visual name="base_fixed_joint_lump__lidar_visual_16">
        <pose>-0.2366 0 0.09243 0 0 -1.5708</pose>
        <geometry>
          <mesh>
            <scale>0.65 0.65 0.65</scale>
            <uri>meshes/lidar.dae</uri>
          </mesh>
        </geometry>
      </visual>
      <visual name="base_fixed_joint_lump__top_shell_visual_17">
        <pose>0 0 0 0 0 0</pose>
        <geometry>
          <mesh>
            <scale>0.65 0.65 0.65</scale>
            <uri>meshes/top_shell.dae</uri>
          </mesh>
        </geometry>
      </visual>
      <visual name="base_fixed_joint_lump__imu_link_visual_18">
        <pose>0.16172 0.0054275 0.033332 0 0 1.5708</pose>
        <geometry>
          <box>
            <size>0.0156 0.0156 0.0065</size>
          </box>
        </geometry>
      </visual>
      <!-- Sensors -->
      <sensor name="imu_sensor" type="imu">
        <always_on>1</always_on>
        <update_rate>400</update_rate>
        <imu>
                    <enable_orientation>0</enable_orientation>
                    <angular_velocity>
                        <x>
                            <noise type="gaussian">
                                <mean>0</mean>
                                <stddev>0.009</stddev>
                                <bias_mean>0.00075</bias_mean>
                                <bias_stddev>0.005</bias_stddev>
                                <dynamic_bias_stddev>0.00002</dynamic_bias_stddev>
                                <dynamic_bias_correlation_time>400.0</dynamic_bias_correlation_time>
                                <precision>0.00025</precision>
                            </noise>
                        </x>
                        <y>
                            <noise type="gaussian">
                                <mean>0</mean>
                                <stddev>0.009</stddev>
                                <bias_mean>0.00075</bias_mean>
                                <bias_stddev>0.005</bias_stddev>
                                <dynamic_bias_stddev>0.00002</dynamic_bias_stddev>
                                <dynamic_bias_correlation_time>400.0</dynamic_bias_correlation_time>
                                <precision>0.00025</precision>
                            </noise>
                        </y>
                        <z>
                            <noise type="gaussian">
                                <mean>0</mean>
                                <stddev>0.009</stddev>
                                <bias_mean>0.00075</bias_mean>
                                <bias_stddev>0.005</bias_stddev>
                                <dynamic_bias_stddev>0.00002</dynamic_bias_stddev>
                                <dynamic_bias_correlation_time>400.0</dynamic_bias_correlation_time>
                                <precision>0.00025</precision>
                            </noise>
                        </z>
                    </angular_velocity>
                    <linear_acceleration>
                        <x>
                            <noise type="gaussian">
                                <mean>0</mean>
                                <stddev>0.021</stddev>
                                <bias_mean>0.05</bias_mean>
                                <bias_stddev>0.0075</bias_stddev>
                                <dynamic_bias_stddev>0.000375</dynamic_bias_stddev>
                                <dynamic_bias_correlation_time>175.0</dynamic_bias_correlation_time>
                                <precision>0.005</precision>
                            </noise>
                        </x>
                        <y>
                            <noise type="gaussian">
                                <mean>0</mean>
                                <stddev>0.021</stddev>
                                <bias_mean>0.05</bias_mean>
                                <bias_stddev>0.0075</bias_stddev>
                                <dynamic_bias_stddev>0.000375</dynamic_bias_stddev>
                                <dynamic_bias_correlation_time>175.0</dynamic_bias_correlation_time>
                                <precision>0.005</precision>
                            </noise>
                        </y>
                        <z>
                            <noise type="gaussian">
                                <mean>0</mean>
                                <stddev>0.021</stddev>
                                <bias_mean>0.05</bias_mean>
                                <bias_stddev>0.0075</bias_stddev>
                                <dynamic_bias_stddev>0.000375</dynamic_bias_stddev>
                                <dynamic_bias_correlation_time>175.0</dynamic_bias_correlation_time>
                                <precision>0.005</precision>
                            </noise>
                        </z>
                    </linear_acceleration>
                </imu>
        <pose frame="">0.249 0.008 0.046 0.000 -0.000 1.571</pose>
      </sensor>
      <sensor name="perception_head_imu_sensor" type="imu">
        <always_on>1</always_on>
        <update_rate>200</update_rate>
        <imu>
                    <enable_orientation>0</enable_orientation>
                    <angular_velocity>
                        <x>
                            <noise type="gaussian">
                                <mean>0</mean>
                                <stddev>0.009</stddev>
                                <bias_mean>0.00075</bias_mean>
                                <bias_stddev>0.005</bias_stddev>
                                <dynamic_bias_stddev>0.00002</dynamic_bias_stddev>
                                <dynamic_bias_correlation_time>400.0</dynamic_bias_correlation_time>
                                <precision>0.00025</precision>
                            </noise>
                        </x>
                        <y>
                            <noise type="gaussian">
                                <mean>0</mean>
                                <stddev>0.009</stddev>
                                <bias_mean>0.00075</bias_mean>
                                <bias_stddev>0.005</bias_stddev>
                                <dynamic_bias_stddev>0.00002</dynamic_bias_stddev>
                                <dynamic_bias_correlation_time>400.0</dynamic_bias_correlation_time>
                                <precision>0.00025</precision>
                            </noise>
                        </y>
                        <z>
                            <noise type="gaussian">
                                <mean>0</mean>
                                <stddev>0.009</stddev>
                                <bias_mean>0.00075</bias_mean>
                                <bias_stddev>0.005</bias_stddev>
                                <dynamic_bias_stddev>0.00002</dynamic_bias_stddev>
                                <dynamic_bias_correlation_time>400.0</dynamic_bias_correlation_time>
                                <precision>0.00025</precision>
                            </noise>
                        </z>
                    </angular_velocity>
                    <linear_acceleration>
                        <x>
                            <noise type="gaussian">
                                <mean>0</mean>
                                <stddev>0.021</stddev>
                                <bias_mean>0.05</bias_mean>
                                <bias_stddev>0.0075</bias_stddev>
                                <dynamic_bias_stddev>0.000375</dynamic_bias_stddev>
                                <dynamic_bias_correlation_time>175.0</dynamic_bias_correlation_time>
                                <precision>0.005</precision>
                            </noise>
                        </x>
                        <y>
                            <noise type="gaussian">
                                <mean>0</mean>
                                <stddev>0.021</stddev>
                                <bias_mean>0.05</bias_mean>
                                <bias_stddev>0.0075</bias_stddev>
                                <dynamic_bias_stddev>0.000375</dynamic_bias_stddev>
                                <dynamic_bias_correlation_time>175.0</dynamic_bias_correlation_time>
                                <precision>0.005</precision>
                            </noise>
                        </y>
                        <z>
                            <noise type="gaussian">
                                <mean>0</mean>
                                <stddev>0.021</stddev>
                                <bias_mean>0.05</bias_mean>
                                <bias_stddev>0.0075</bias_stddev>
                                <dynamic_bias_stddev>0.000375</dynamic_bias_stddev>
                                <dynamic_bias_correlation_time>175.0</dynamic_bias_correlation_time>
                                <precision>0.005</precision>
                            </noise>
                        </z>
                    </linear_acceleration>
                </imu>
        <pose frame="">-0.327 -0.005 0.206 0.000 0.000 -1.571</pose>
      </sensor>
      <sensor name="front_laser" type="gpu_lidar">
        <visualize>0</visualize>
        <update_rate>10</update_rate>
        <lidar>
          <scan>
            <horizontal>
              <samples>1800</samples>
              <resolution>1.0</resolution>
              <min_angle>-3.14159</min_angle>
              <max_angle>3.14159</max_angle>
            </horizontal>
            <vertical>
              <samples>16</samples>
              <resolution>1</resolution>
              <min_angle>-0.261799</min_angle>
              <max_angle>0.261799</max_angle>
            </vertical>
          </scan>
          <range>
            <min>0.05</min>
            <max>100</max>
            <resolution>0.01</resolution>
          </range>
          <noise>
            <type>gaussian</type>
            <mean>0</mean>
            <stddev>0.01</stddev>
          </noise>
        </lidar>
        <pose frame="">-0.364 0.000 0.142 0.000 0.000 -1.571</pose>
      </sensor>
      <sensor name="front_bpearl" type="gpu_lidar">
        <visualize>0</visualize>
        <update_rate>10</update_rate>
        <lidar>
          <scan>
            <horizontal>
              <samples>440</samples>
              <resolution>1</resolution>
              <min_angle>-3.14159</min_angle>
              <max_angle>3.14159</max_angle>
            </horizontal>
            <vertical>
              <samples>32</samples>
              <resolution>1</resolution>
              <min_angle>0.040360739</min_angle>
              <max_angle>1.562069681</max_angle>
            </vertical>
          </scan>
          <range>
            <min>0.3</min>
            <max>31</max>
            <resolution>0.001</resolution>
          </range>
          <noise>
            <type>gaussian</type>
            <mean>0</mean>
            <stddev>0.008</stddev>
          </noise>
        </lidar>
        <pose frame="">0.524 0.000 -0.042 -2.576 0.245 -1.936</pose>
      </sensor>
      <sensor name="rear_bpearl" type="gpu_lidar">
        <visualize>0</visualize>
        <update_rate>10</update_rate>
        <lidar>
          <scan>
            <horizontal>
              <samples>440</samples>
              <resolution>1</resolution>
              <min_angle>-3.14159</min_angle>
              <max_angle>3.14159</max_angle>
            </horizontal>
            <vertical>
              <samples>32</samples>
              <resolution>1</resolution>
              <min_angle>0.040360739</min_angle>
              <max_angle>1.562069681</max_angle>
            </vertical>
          </scan>
          <range>
            <min>0.3</min>
            <max>31</max>
            <resolution>0.001</resolution>
          </range>
          <noise>
            <type>gaussian</type>
            <mean>0</mean>
            <stddev>0.008</stddev>
          </noise>
        </lidar>
        <pose frame="">-0.524 -0.000 -0.042 -2.576 0.245 1.206</pose>
      </sensor>
      <sensor name="camera_0" type="camera">
        <always_on>1</always_on>
        <update_rate>20</update_rate>
        <pose frame="">-0.400 -0.050 0.229 -0.006 0.011 3.133</pose>
        <camera name="camera_0">
          <horizontal_fov>2.19911</horizontal_fov>
          <lens>
            <intrinsics>
              <!-- fx = fy = width / ( 2 * tan (hfov / 2 ) ) -->
              <fx>183.43</fx>
              <fy>183.43</fy>
              <!-- cx = ( width + 1 ) / 2 -->
              <cx>360.5</cx>
              <!-- cy = ( height + 1 ) / 2 -->
              <cy>270.5</cy>
              <s>0</s>
            </intrinsics>
          </lens>
          <image>
            <width>720</width>
            <height>540</height>
          </image>
          <clip>
            <near>0.02</near>
            <far>100</far>
          </clip>
            <noise>
            <type>gaussian</type>
              <mean>0</mean>
              <stddev>0.007</stddev>
            </noise>
        </camera>
      </sensor>
      <sensor name="camera_1" type="camera">
        <always_on>1</always_on>
        <update_rate>20</update_rate>
        <pose frame="">-0.400 0.049 0.229 -0.006 0.0 3.139</pose>
        <camera name="camera_1">
          <horizontal_fov>2.19911</horizontal_fov>
          <lens>
            <intrinsics>
              <!-- fx = fy = width / ( 2 * tan (hfov / 2 ) ) -->
              <fx>183.43</fx>
              <fy>183.43</fy>
              <!-- cx = ( width + 1 ) / 2 -->
              <cx>360.5</cx>
              <!-- cy = ( height + 1 ) / 2 -->
              <cy>270.5</cy>
              <s>0</s>
            </intrinsics>
          </lens>
          <image>
            <width>728</width>
            <height>544</height>
          </image>
          <clip>
            <near>0.02</near>
            <far>100</far>
          </clip>
            <noise>
            <type>gaussian</type>
              <mean>0</mean>
              <stddev>0.007</stddev>
            </noise>
        </camera>
      </sensor>
      <sensor name="camera_2" type="camera">
        <always_on>1</always_on>
        <update_rate>20</update_rate>
        <pose frame="">-0.379 -0.050 0.265 -0.009 -1.572 -0.004</pose>
        <camera name="camera_2">
          <horizontal_fov>2.19911</horizontal_fov>
          <lens>
            <intrinsics>
              <!-- fx = fy = width / ( 2 * tan (hfov / 2 ) ) -->
              <fx>183.43</fx>
              <fy>183.43</fy>
              <!-- cx = ( width + 1 ) / 2 -->
              <cx>360.5</cx>
              <!-- cy = ( height + 1 ) / 2 -->
              <cy>270.5</cy>
              <s>0</s>
            </intrinsics>
          </lens>
          <image>
            <width>720</width>
            <height>540</height>
          </image>
          <clip>
            <near>0.02</near>
            <far>100</far>
          </clip>
            <noise>
            <type>gaussian</type>
              <mean>0</mean>
              <stddev>0.007</stddev>
            </noise>
        </camera>
      </sensor>
      <sensor name="camera_3" type="camera">
        <always_on>1</always_on>
        <update_rate>20</update_rate>
        <pose frame="">-0.348 -0.073 0.237 0.004 -0.172 -1.575</pose>
        <camera name="camera_3">
          <horizontal_fov>2.19911</horizontal_fov>
          <lens>
            <intrinsics>
              <!-- fx = fy = width / ( 2 * tan (hfov / 2 ) ) -->
              <fx>183.43</fx>
              <fy>183.43</fy>
              <!-- cx = ( width + 1 ) / 2 -->
              <cx>360.5</cx>
              <!-- cy = ( height + 1 ) / 2 -->
              <cy>270.5</cy>
              <s>0</s>
            </intrinsics>
          </lens>
          <image>
            <width>720</width>
            <height>540</height>
          </image>
          <clip>
            <near>0.02</near>
            <far>100</far>
          </clip>
            <noise>
            <type>gaussian</type>
              <mean>0</mean>
              <stddev>0.007</stddev>
            </noise>
        </camera>
      </sensor>
      <sensor name="camera_4" type="camera">
        <always_on>1</always_on>
        <update_rate>20</update_rate>
        <pose frame="">-0.399 -0.000 0.228 -0.009 -0.002 3.136</pose>
        <camera name="camera_4">
          <horizontal_fov>2.19911</horizontal_fov>
          <lens>
            <intrinsics>
              <!-- fx = fy = width / ( 2 * tan (hfov / 2 ) ) -->
              <fx>183.43</fx>
              <fy>183.43</fy>
              <!-- cx = ( width + 1 ) / 2 -->
              <cx>360.5</cx>
              <!-- cy = ( height + 1 ) / 2 -->
              <cy>270.5</cy>
              <s>0</s>
            </intrinsics>
          </lens>
          <image>
            <width>720</width>
            <height>540</height>
          </image>
          <clip>
            <near>0.02</near>
            <far>100</far>
          </clip>
            <noise>
            <type>gaussian</type>
              <mean>0</mean>
              <stddev>0.007</stddev>
            </noise>
        </camera>
      </sensor>
      <sensor name="camera_5" type="camera">
        <always_on>1</always_on>
        <update_rate>20</update_rate>
        <pose frame="">-0.347 0.072 0.236 -0.012 -0.171 1.569</pose>
        <camera name="camera_5">
          <horizontal_fov>2.19911</horizontal_fov>
          <lens>
            <intrinsics>
              <!-- fx = fy = width / ( 2 * tan (hfov / 2 ) ) -->
              <fx>183.43</fx>
              <fy>183.43</fy>
              <!-- cx = ( width + 1 ) / 2 -->
              <cx>360.5</cx>
              <!-- cy = ( height + 1 ) / 2 -->
              <cy>270.5</cy>
              <s>0</s>
            </intrinsics>
          </lens>
          <image>
            <width>720</width>
            <height>540</height>
          </image>
          <clip>
            <near>0.02</near>
            <far>100</far>
          </clip>
            <noise>
            <type>gaussian</type>
              <mean>0</mean>
              <stddev>0.007</stddev>
            </noise>
        </camera>
      </sensor>
      <sensor name="camera_6" type="camera">
        <always_on>1</always_on>
        <update_rate>20</update_rate>
        <pose frame="">-0.379 0.050 0.265 -0.009 -1.572 -0.004</pose>
        <camera name="camera_6">
          <horizontal_fov>2.19911</horizontal_fov>
          <lens>
            <intrinsics>
              <!-- fx = fy = width / ( 2 * tan (hfov / 2 ) ) -->
              <fx>183.43</fx>
              <fy>183.43</fy>
              <!-- cx = ( width + 1 ) / 2 -->
              <cx>360.5</cx>
              <!-- cy = ( height + 1 ) / 2 -->
              <cy>270.5</cy>
              <s>0</s>
            </intrinsics>
          </lens>
          <image>
            <width>720</width>
            <height>540</height>
          </image>
          <clip>
            <near>0.02</near>
            <far>100</far>
          </clip>
            <noise>
            <type>gaussian</type>
              <mean>0</mean>
              <stddev>0.007</stddev>
            </noise>
        </camera>
      </sensor>
      <!-- Lights -->
      <!-- <light name="light_up" type="spot">
        <pose frame="">-0.332 0.0 0.28 0.0 3.141 0.0</pose>
        <attenuation>
          <range>50</range>
          <linear>0</linear>
          <constant>0.1</constant>
          <quadratic>0.0025</quadratic>
        </attenuation>
        <diffuse>0.8 0.8 0.5 1</diffuse>
        <specular>0.8 0.8 0.5 1</specular>
        <spot>
          <inner_angle>1.2</inner_angle>
          <outer_angle>1.3</outer_angle>
          <falloff>1</falloff>
        </spot>
        <direction>0 0 1</direction>
      </light>
      <light name="light_forward" type="spot">
        <pose frame="">-0.41 0.0 0.265 0.0 1.57 0.0</pose>
        <attenuation>
          <range>50</range>
          <linear>0</linear>
          <constant>0.1</constant>
          <quadratic>0.0025</quadratic>
        </attenuation>
        <diffuse>0.8 0.8 0.5 1</diffuse>
        <specular>0.8 0.8 0.5 1</specular>
        <spot>
          <inner_angle>1.2</inner_angle>
          <outer_angle>1.3</outer_angle>
          <falloff>1</falloff>
        </spot>
        <direction>0 0 1</direction>
      </light>
      <light name="light_left" type="spot">
        <pose frame="">-0.348 -0.077 0.273 1.743 0.004 3.138</pose>
        <attenuation>
          <range>50</range>
          <linear>0</linear>
          <constant>0.1</constant>
          <quadratic>0.0025</quadratic>
        </attenuation>
        <diffuse>0.8 0.8 0.5 1</diffuse>
        <specular>0.8 0.8 0.5 1</specular>
        <spot>
          <inner_angle>1.2</inner_angle>
          <outer_angle>1.3</outer_angle>
          <falloff>1</falloff>
        </spot>
        <direction>0 0 1</direction>
      </light>
      <light name="light_right" type="spot">
        <pose frame="">-0.347 0.076 0.272 1.742 -0.011 -0.003</pose>
        <attenuation>
          <range>50</range>
          <linear>0</linear>
          <constant>0.1</constant>
          <quadratic>0.0025</quadratic>
        </attenuation>
        <diffuse>0.8 0.8 0.5 1</diffuse>
        <specular>0.8 0.8 0.5 1</specular>
        <spot>
          <inner_angle>1.2</inner_angle>
          <outer_angle>1.3</outer_angle>
          <falloff>1</falloff>
        </spot>
        <direction>0 0 1</direction>
      </light> -->
    </link>
    <link name="LF_HIP">
      <pose>0.194935 0.0676 0 2.61799 0 0</pose>
      <inertial>
        <pose>0.03682965 -0.0099411 -0.0053937 0 0 0</pose>
        <mass>2.781</mass>
        <inertia>
          <ixx>0.00329553</ixx>
          <ixy>-1.03882e-05</ixy>
          <ixz>0.000107062</ixz>
          <iyy>0.00504435</iyy>
          <iyz>-0.000319492</iyz>
          <izz>0.0057269</izz>
        </inertia>
      </inertial>
      <collision name="LF_HIP_fixed_joint_lump__LF_HFE_collision">
        <pose>0.038935 -0.007774 -0.00448825 -3.14159 -1.0472 -1.5708</pose>
        <geometry>
          <cylinder>
            <length>0.091</length>
            <radius>0.0325</radius>
          </cylinder>
        </geometry>
      </collision>
      <visual name="LF_HIP_fixed_joint_lump__LF_hip_fixed_visual">
        <pose>0 0 0 -2.61799 0 0</pose>
        <geometry>
          <mesh>
            <scale>0.65 0.65 0.65</scale>
            <uri>meshes/hip_l.dae</uri>
          </mesh>
        </geometry>
      </visual>
      <visual name="LF_HIP_fixed_joint_lump__LF_HFE_visual_1">
        <pose>0.038935 -0.0471783 -0.02723825 -3.14159 0.523599 -1.5708</pose>
        <geometry>
          <mesh>
            <scale>0.65 0.65 0.65</scale>
            <uri>meshes/drive.dae</uri>
          </mesh>
        </geometry>
      </visual>
    </link>
    <joint name="LF_HAA" type="revolute">
      <child>LF_HIP</child>
      <parent>base</parent>
      <axis>
        <xyz>1 0 0</xyz>
        <limit>
          <lower>-0.72</lower>
          <upper>0.49</upper>
          <effort>80</effort>
          <velocity>7.5</velocity>
        </limit>
        <dynamics>
          <damping>0</damping>
          <friction>0</friction>
          <spring_reference>0</spring_reference>
          <spring_stiffness>0</spring_stiffness>
        </dynamics>
        <use_parent_model_frame>0</use_parent_model_frame>
      </axis>
    </joint>
    <link name="LF_THIGH">
      <pose>0.23387 0.1220765 0 0 0 1.5708</pose>
      <inertial>
        <pose>0.02002975 2.99e-05 -0.1597024 0 0 0</pose>
        <mass>3.071</mass>
        <inertia>
          <ixx>0.0295638</ixx>
          <ixy>4.42919e-05</ixy>
          <ixz>0.00414243</ixz>
          <iyy>0.029904</iyy>
          <iyz>9.448e-05</iyz>
          <izz>0.00486108</izz>
        </inertia>
      </inertial>
      <collision name="LF_THIGH_fixed_joint_lump__LF_thigh_fixed_collision">
        <pose>0.026 0 0 1.5708 0 -1.5708</pose>
        <geometry>
          <cylinder>
            <length>0.052</length>
            <radius>0.04225</radius>
          </cylinder>
        </geometry>
      </collision>
      <collision name="LF_THIGH_fixed_joint_lump__LF_thigh_fixed_collision_1">
        <pose>0.0195 0 -0.0918541 0 0 -1.5708</pose>
        <geometry>
          <box>
            <size>0.04875 0.039 0.18370755</size>
          </box>
        </geometry>
      </collision>
      <collision name="LF_THIGH_fixed_joint_lump__LF_KFE_collision_2">
        <pose>0.019695 0 -0.18525 0 1.5708 0</pose>
        <geometry>
          <cylinder>
            <length>0.091</length>
            <radius>0.0325</radius>
          </cylinder>
        </geometry>
      </collision>
      <visual name="LF_THIGH_fixed_joint_lump__LF_thigh_fixed_visual">
        <pose>0 0 0 0 0 -1.5708</pose>
        <geometry>
          <mesh>
            <scale>0.65 0.65 0.65</scale>
            <uri>meshes/thigh.dae</uri>
          </mesh>
        </geometry>
      </visual>
      <visual name="LF_THIGH_fixed_joint_lump__LF_KFE_visual_1">
        <pose>0.065195 0 -0.18525 0 0 0</pose>
        <geometry>
          <mesh>
            <scale>0.65 0.65 0.65</scale>
            <uri>meshes/drive.dae</uri>
          </mesh>
        </geometry>
      </visual>
    </link>
    <joint name="LF_HFE" type="revolute">
      <child>LF_THIGH</child>
      <parent>LF_HIP</parent>
      <axis>
        <xyz>1 0 0</xyz>
        <limit>
          <lower>-9.42478</lower>
          <upper>9.42478</upper>
          <effort>80</effort>
          <velocity>7.5</velocity>
        </limit>
        <dynamics>
          <damping>0</damping>
          <friction>0</friction>
          <spring_reference>0</spring_reference>
          <spring_stiffness>0</spring_stiffness>
        </dynamics>
        <use_parent_model_frame>0</use_parent_model_frame>
      </axis>
    </joint>
    <link name="LF_SHANK">
      <pose>0.23387 0.1872715 -0.18525 0 0 1.5708</pose>
      <inertial>
        <pose>0.0035503 -0.03981445 -0.052429 0 0 0</pose>
        <mass>0.58842</mass>
        <inertia>
          <ixx>0.0101611</ixx>
          <ixy>-5.35713e-05</ixy>
          <ixz>-2.26604e-05</ixz>
          <iyy>0.00881038</iyy>
          <iyz>-0.00181935</iyz>
          <izz>0.00154978</izz>
        </inertia>
      </inertial>
      <collision name="LF_SHANK_fixed_joint_lump__LF_shank_fixed_collision">
        <pose>0.013 0 0 1.5708 0 -1.5708</pose>
        <geometry>
          <cylinder>
            <length>0.026</length>
            <radius>0.039</radius>
          </cylinder>
        </geometry>
      </collision>
      <collision name="LF_SHANK_fixed_joint_lump__LF_shank_fixed_collision_1">
        <pose>0.013 -0.03737435 0 1.5708 0 -1.5708</pose>
        <geometry>
          <box>
            <size>0.0747487 0.043875 0.026</size>
          </box>
        </geometry>
      </collision>
      <collision name="LF_SHANK_fixed_joint_lump__LF_FOOT_collision_2">
        <pose>0.0084825 -0.0571675 -0.10984025 0 0 -1.5708</pose>
        <geometry>
          <cylinder>
            <length>0.1836276</length>
            <radius>0.011375</radius>
          </cylinder>
        </geometry>
      </collision>
      <collision name="LF_SHANK_fixed_joint_lump__LF_FOOT_collision_3">
        <pose>0.0084825 -0.0571675 -0.2050555 0 0 -1.5708</pose>
        <geometry>
          <sphere>
            <radius>0.0195</radius>
          </sphere>
        </geometry>
      </collision>
      <visual name="LF_SHANK_fixed_joint_lump__LF_shank_fixed_visual">
        <pose>0 0 0 0 0 -1.5708</pose>
        <geometry>
          <mesh>
            <scale>0.65 0.65 0.65</scale>
            <uri>meshes/shank_l.dae</uri>
          </mesh>
        </geometry>
      </visual>
      <visual name="LF_SHANK_fixed_joint_lump__LF_FOOT_visual_1">
        <pose>0.0084825 -0.0571675 -0.2196805 0 0 -2.35619</pose>
        <geometry>
          <mesh>
            <scale>0.65 0.65 0.65</scale>
            <uri>meshes/foot.dae</uri>
          </mesh>
        </geometry>
      </visual>
    </link>
    <joint name="LF_KFE" type="revolute">
      <child>LF_SHANK</child>
      <parent>LF_THIGH</parent>
      <axis>
        <xyz>1 0 0</xyz>
        <limit>
          <lower>-9.42478</lower>
          <upper>9.42478</upper>
          <effort>80</effort>
          <velocity>7.5</velocity>
        </limit>
        <dynamics>
          <damping>0</damping>
          <friction>0</friction>
          <spring_reference>0</spring_reference>
          <spring_stiffness>0</spring_stiffness>
        </dynamics>
        <use_parent_model_frame>0</use_parent_model_frame>
      </axis>
    </joint>
    <link name="LH_HIP">
      <pose>-0.194935 0.0676 0 -2.61799 0 3.14159</pose>
      <inertial>
        <pose>0.03689595 0.0099411 -0.0053937 0 0 0</pose>
        <mass>2.781</mass>
        <inertia>
          <ixx>0.00329553</ixx>
          <ixy>-1.10053e-05</ixy>
          <ixz>-0.000109121</ixz>
          <iyy>0.00504617</iyy>
          <iyz>0.000319492</iyz>
          <izz>0.00572872</izz>
        </inertia>
      </inertial>
      <collision name="LH_HIP_fixed_joint_lump__LH_HFE_collision">
        <pose>0.038935 0.007774 -0.00448825 -3.14159 -1.0472 1.5708</pose>
        <geometry>
          <cylinder>
            <length>0.091</length>
            <radius>0.0325</radius>
          </cylinder>
        </geometry>
      </collision>
      <visual name="LH_HIP_fixed_joint_lump__LH_hip_fixed_visual">
        <pose>0 0 0 2.61799 0 0</pose>
        <geometry>
          <mesh>
            <scale>0.65 0.65 0.65</scale>
            <uri>meshes/hip_r.dae</uri>
          </mesh>
        </geometry>
      </visual>
      <visual name="LH_HIP_fixed_joint_lump__LH_HFE_visual_1">
        <pose>0.038935 0.0471783 -0.02723825 -3.14159 0.523599 1.5708</pose>
        <geometry>
          <mesh>
            <scale>0.65 0.65 0.65</scale>
            <uri>meshes/drive.dae</uri>
          </mesh>
        </geometry>
      </visual>
    </link>
    <joint name="LH_HAA" type="revolute">
      <child>LH_HIP</child>
      <parent>base</parent>
      <axis>
        <xyz>-1 0 0</xyz>
        <limit>
          <lower>-0.72</lower>
          <upper>0.49</upper>
          <effort>80</effort>
          <velocity>7.5</velocity>
        </limit>
        <dynamics>
          <damping>0</damping>
          <friction>0</friction>
          <spring_reference>0</spring_reference>
          <spring_stiffness>0</spring_stiffness>
        </dynamics>
        <use_parent_model_frame>0</use_parent_model_frame>
      </axis>
    </joint>
    <link name="LH_THIGH">
      <pose>-0.23387 0.1220765 0 0 0 1.5708</pose>
      <inertial>
        <pose>0.02002975 2.99e-05 -0.1597024 0 0 0</pose>
        <mass>3.071</mass>
        <inertia>
          <ixx>0.0295638</ixx>
          <ixy>4.43959e-05</ixy>
          <ixz>0.00414243</ixz>
          <iyy>0.029904</iyy>
          <iyz>0.000114794</iyz>
          <izz>0.00486108</izz>
        </inertia>
      </inertial>
      <collision name="LH_THIGH_fixed_joint_lump__LH_thigh_fixed_collision">
        <pose>0.026 0 0 1.5708 0 -1.5708</pose>
        <geometry>
          <cylinder>
            <length>0.052</length>
            <radius>0.04225</radius>
          </cylinder>
        </geometry>
      </collision>
      <collision name="LH_THIGH_fixed_joint_lump__LH_thigh_fixed_collision_1">
        <pose>0.0195 0 -0.0918541 0 0 -1.5708</pose>
        <geometry>
          <box>
            <size>0.04875 0.039 0.18370755</size>
          </box>
        </geometry>
      </collision>
      <collision name="LH_THIGH_fixed_joint_lump__LH_KFE_collision_2">
        <pose>0.019695 0 -0.18525 0 1.5708 0</pose>
        <geometry>
          <cylinder>
            <length>0.091</length>
            <radius>0.0325</radius>
          </cylinder>
        </geometry>
      </collision>
      <visual name="LH_THIGH_fixed_joint_lump__LH_thigh_fixed_visual">
        <pose>0 0 0 0 0 -1.5708</pose>
        <geometry>
          <mesh>
            <scale>0.65 0.65 0.65</scale>
            <uri>meshes/thigh.dae</uri>
          </mesh>
        </geometry>
      </visual>
      <visual name="LH_THIGH_fixed_joint_lump__LH_KFE_visual_1">
        <pose>0.065195 0 -0.18525 0 0 0</pose>
        <geometry>
          <mesh>
            <scale>0.65 0.65 0.65</scale>
            <uri>meshes/drive.dae</uri>
          </mesh>
        </geometry>
      </visual>
    </link>
    <joint name="LH_HFE" type="revolute">
      <child>LH_THIGH</child>
      <parent>LH_HIP</parent>
      <axis>
        <xyz>1 0 0</xyz>
        <limit>
          <lower>-9.42478</lower>
          <upper>9.42478</upper>
          <effort>80</effort>
          <velocity>7.5</velocity>
        </limit>
        <dynamics>
          <damping>0</damping>
          <friction>0</friction>
          <spring_reference>0</spring_reference>
          <spring_stiffness>0</spring_stiffness>
        </dynamics>
        <use_parent_model_frame>0</use_parent_model_frame>
      </axis>
    </joint>
    <link name="LH_SHANK">
      <pose>-0.23387 0.1872715 -0.18525 0 0 1.5708</pose>
      <inertial>
        <pose>0.0035503 0.03981445 -0.052429 0 0 0</pose>
        <mass>0.58842</mass>
        <inertia>
          <ixx>0.0101611</ixx>
          <ixy>5.35713e-05</ixy>
          <ixz>-2.26604e-05</ixz>
          <iyy>0.00881038</iyy>
          <iyz>0.00181935</iyz>
          <izz>0.00154978</izz>
        </inertia>
      </inertial>
      <collision name="LH_SHANK_fixed_joint_lump__LH_shank_fixed_collision">
        <pose>0.013 0 0 1.5708 0 -1.5708</pose>
        <geometry>
          <cylinder>
            <length>0.026</length>
            <radius>0.039</radius>
          </cylinder>
        </geometry>
      </collision>
      <collision name="LH_SHANK_fixed_joint_lump__LH_shank_fixed_collision_1">
        <pose>0.013 0.03737435 0 1.5708 0 -1.5708</pose>
        <geometry>
          <box>
            <size>0.0747487 0.043875 0.026</size>
          </box>
        </geometry>
      </collision>
      <collision name="LH_SHANK_fixed_joint_lump__LH_FOOT_collision_2">
        <pose>0.0084825 0.0571675 -0.10984025 0 0 -1.5708</pose>
        <geometry>
          <cylinder>
            <length>0.1836276</length>
            <radius>0.011375</radius>
          </cylinder>
        </geometry>
      </collision>
      <collision name="LH_SHANK_fixed_joint_lump__LH_FOOT_collision_3">
        <pose>0.0084825 0.0571675 -0.2050555 0 0 -1.5708</pose>
        <geometry>
          <sphere>
            <radius>0.0195</radius>
          </sphere>
        </geometry>
      </collision>
      <visual name="LH_SHANK_fixed_joint_lump__LH_shank_fixed_visual">
        <pose>0 0 0 0 0 1.5708</pose>
        <geometry>
          <mesh>
            <scale>0.65 0.65 0.65</scale>
            <uri>meshes/shank_r.dae</uri>
          </mesh>
        </geometry>
      </visual>
      <visual name="LH_SHANK_fixed_joint_lump__LH_FOOT_visual_1">
        <pose>0.0084825 0.0571675 -0.2196805 0 0 2.35619</pose>
        <geometry>
          <mesh>
            <scale>0.65 0.65 0.65</scale>
            <uri>meshes/foot.dae</uri>
          </mesh>
        </geometry>
      </visual>
    </link>
    <joint name="LH_KFE" type="revolute">
      <child>LH_SHANK</child>
      <parent>LH_THIGH</parent>
      <axis>
        <xyz>1 0 0</xyz>
        <limit>
          <lower>-9.42478</lower>
          <upper>9.42478</upper>
          <effort>80</effort>
          <velocity>7.5</velocity>
        </limit>
        <dynamics>
          <damping>0</damping>
          <friction>0</friction>
          <spring_reference>0</spring_reference>
          <spring_stiffness>0</spring_stiffness>
        </dynamics>
        <use_parent_model_frame>0</use_parent_model_frame>
      </axis>
    </joint>
    <link name="RF_HIP">
      <pose>0.194935 -0.0676 0 -2.61799 0 0</pose>
      <inertial>
        <pose>0.03689595 0.0099411 -0.0053937 0 0 0</pose>
        <mass>2.781</mass>
        <inertia>
          <ixx>0.00329553</ixx>
          <ixy>-1.10053e-05</ixy>
          <ixz>-0.000109121</ixz>
          <iyy>0.00504617</iyy>
          <iyz>0.000319492</iyz>
          <izz>0.00572872</izz>
        </inertia>
      </inertial>
      <collision name="RF_HIP_fixed_joint_lump__RF_HFE_collision">
        <pose>0.038935 0.007774 -0.00448825 3.14159 -1.0472 1.5708</pose>
        <geometry>
          <cylinder>
            <length>0.091</length>
            <radius>0.0325</radius>
          </cylinder>
        </geometry>
      </collision>
      <visual name="RF_HIP_fixed_joint_lump__RF_hip_fixed_visual">
        <pose>0 0 0 2.61799 0 0</pose>
        <geometry>
          <mesh>
            <scale>0.65 0.65 0.65</scale>
            <uri>meshes/hip_r.dae</uri>
          </mesh>
        </geometry>
      </visual>
      <visual name="RF_HIP_fixed_joint_lump__RF_HFE_visual_1">
        <pose>0.038935 0.0471783 -0.02723825 3.14159 0.523599 1.5708</pose>
        <geometry>
          <mesh>
            <scale>0.65 0.65 0.65</scale>
            <uri>meshes/drive.dae</uri>
          </mesh>
        </geometry>
      </visual>
    </link>
    <joint name="RF_HAA" type="revolute">
      <child>RF_HIP</child>
      <parent>base</parent>
      <axis>
        <xyz>1 0 0</xyz>
        <limit>
          <lower>-0.49</lower>
          <upper>0.72</upper>
          <effort>80</effort>
          <velocity>7.5</velocity>
        </limit>
        <dynamics>
          <damping>0</damping>
          <friction>0</friction>
          <spring_reference>0</spring_reference>
          <spring_stiffness>0</spring_stiffness>
        </dynamics>
        <use_parent_model_frame>0</use_parent_model_frame>
      </axis>
    </joint>
    <link name="RF_THIGH">
      <pose>0.23387 -0.1220765 0 0 0 -1.5708</pose>
      <inertial>
        <pose>0.02002975 2.99e-05 -0.1597024 0 0 0</pose>
        <mass>3.071</mass>
        <inertia>
          <ixx>0.0295638</ixx>
          <ixy>4.43959e-05</ixy>
          <ixz>0.00414243</ixz>
          <iyy>0.029904</iyy>
          <iyz>0.000114794</iyz>
          <izz>0.00486108</izz>
        </inertia>
      </inertial>
      <collision name="RF_THIGH_fixed_joint_lump__RF_thigh_fixed_collision">
        <pose>0.026 0 0 1.5708 0 1.5708</pose>
        <geometry>
          <cylinder>
            <length>0.052</length>
            <radius>0.04225</radius>
          </cylinder>
        </geometry>
      </collision>
      <collision name="RF_THIGH_fixed_joint_lump__RF_thigh_fixed_collision_1">
        <pose>0.0195 0 -0.0918541 0 0 1.5708</pose>
        <geometry>
          <box>
            <size>0.04875 0.039 0.18370755</size>
          </box>
        </geometry>
      </collision>
      <collision name="RF_THIGH_fixed_joint_lump__RF_KFE_collision_2">
        <pose>0.019695 0 -0.18525 0 1.5708 0</pose>
        <geometry>
          <cylinder>
            <length>0.091</length>
            <radius>0.0325</radius>
          </cylinder>
        </geometry>
      </collision>
      <visual name="RF_THIGH_fixed_joint_lump__RF_thigh_fixed_visual">
        <pose>0 0 0 0 0 -1.5708</pose>
        <geometry>
          <mesh>
            <scale>0.65 0.65 0.65</scale>
            <uri>meshes/thigh.dae</uri>
          </mesh>
        </geometry>
      </visual>
      <visual name="RF_THIGH_fixed_joint_lump__RF_KFE_visual_1">
        <pose>0.065195 0 -0.18525 0 0 0</pose>
        <geometry>
          <mesh>
            <scale>0.65 0.65 0.65</scale>
            <uri>meshes/drive.dae</uri>
          </mesh>
        </geometry>
      </visual>
    </link>
    <joint name="RF_HFE" type="revolute">
      <child>RF_THIGH</child>
      <parent>RF_HIP</parent>
      <axis>
        <xyz>-1 0 0</xyz>
        <limit>
          <lower>-9.42478</lower>
          <upper>9.42478</upper>
          <effort>80</effort>
          <velocity>7.5</velocity>
        </limit>
        <dynamics>
          <damping>0</damping>
          <friction>0</friction>
          <spring_reference>0</spring_reference>
          <spring_stiffness>0</spring_stiffness>
        </dynamics>
        <use_parent_model_frame>0</use_parent_model_frame>
      </axis>
    </joint>
    <link name="RF_SHANK">
      <pose>0.23387 -0.1872715 -0.18525 0 0 -1.5708</pose>
      <inertial>
        <pose>0.0035503 0.03981445 -0.052429 0 0 0</pose>
        <mass>0.58842</mass>
        <inertia>
          <ixx>0.0101611</ixx>
          <ixy>5.35713e-05</ixy>
          <ixz>-2.26604e-05</ixz>
          <iyy>0.00881038</iyy>
          <iyz>0.00181935</iyz>
          <izz>0.00154978</izz>
        </inertia>
      </inertial>
      <collision name="RF_SHANK_fixed_joint_lump__RF_shank_fixed_collision">
        <pose>0.013 0 0 1.5708 0 1.5708</pose>
        <geometry>
          <cylinder>
            <length>0.026</length>
            <radius>0.039</radius>
          </cylinder>
        </geometry>
      </collision>
      <collision name="RF_SHANK_fixed_joint_lump__RF_shank_fixed_collision_1">
        <pose>0.013 0.03737435 0 1.5708 0 1.5708</pose>
        <geometry>
          <box>
            <size>0.0747487 0.043875 0.026</size>
          </box>
        </geometry>
      </collision>
      <collision name="RF_SHANK_fixed_joint_lump__RF_FOOT_collision_2">
        <pose>0.0084825 0.0571675 -0.10984025 0 0 1.5708</pose>
        <geometry>
          <cylinder>
            <length>0.1836276</length>
            <radius>0.011375</radius>
          </cylinder>
        </geometry>
      </collision>
      <collision name="RF_SHANK_fixed_joint_lump__RF_FOOT_collision_3">
        <pose>0.0084825 0.0571675 -0.2050555 0 0 1.5708</pose>
        <geometry>
          <sphere>
            <radius>0.0195</radius>
          </sphere>
        </geometry>
      </collision>
      <visual name="RF_SHANK_fixed_joint_lump__RF_shank_fixed_visual">
        <pose>0 0 0 0 0 1.5708</pose>
        <geometry>
          <mesh>
            <scale>0.65 0.65 0.65</scale>
            <uri>meshes/shank_r.dae</uri>
          </mesh>
        </geometry>
      </visual>
      <visual name="RF_SHANK_fixed_joint_lump__RF_FOOT_visual_1">
        <pose>0.0084825 0.0571675 -0.2196805 0 0 2.35619</pose>
        <geometry>
          <mesh>
            <scale>0.65 0.65 0.65</scale>
            <uri>meshes/foot.dae</uri>
          </mesh>
        </geometry>
      </visual>
    </link>
    <joint name="RF_KFE" type="revolute">
      <child>RF_SHANK</child>
      <parent>RF_THIGH</parent>
      <axis>
        <xyz>-1 0 0</xyz>
        <limit>
          <lower>-9.42478</lower>
          <upper>9.42478</upper>
          <effort>80</effort>
          <velocity>7.5</velocity>
        </limit>
        <dynamics>
          <damping>0</damping>
          <friction>0</friction>
          <spring_reference>0</spring_reference>
          <spring_stiffness>0</spring_stiffness>
        </dynamics>
        <use_parent_model_frame>0</use_parent_model_frame>
      </axis>
    </joint>
    <link name="RH_HIP">
      <pose>-0.194935 -0.0676 0 2.61799 0 3.14159</pose>
      <inertial>
        <pose>0.03682965 -0.0099411 -0.0053937 0 0 0</pose>
        <mass>2.781</mass>
        <inertia>
          <ixx>0.00329553</ixx>
          <ixy>-1.03882e-05</ixy>
          <ixz>0.000107062</ixz>
          <iyy>0.00504435</iyy>
          <iyz>-0.000319492</iyz>
          <izz>0.0057269</izz>
        </inertia>
      </inertial>
      <collision name="RH_HIP_fixed_joint_lump__RH_HFE_collision">
        <pose>0.038935 -0.007774 -0.00448825 3.14159 -1.0472 -1.5708</pose>
        <geometry>
          <cylinder>
            <length>0.091</length>
            <radius>0.0325</radius>
          </cylinder>
        </geometry>
      </collision>
      <visual name="RH_HIP_fixed_joint_lump__RH_hip_fixed_visual">
        <pose>0 0 0 -2.61799 0 0</pose>
        <geometry>
          <mesh>
            <scale>0.65 0.65 0.65</scale>
            <uri>meshes/hip_l.dae</uri>
          </mesh>
        </geometry>
      </visual>
      <visual name="RH_HIP_fixed_joint_lump__RH_HFE_visual_1">
        <pose>0.038935 -0.0471783 -0.02723825 3.14159 0.523599 -1.5708</pose>
        <geometry>
          <mesh>
            <scale>0.65 0.65 0.65</scale>
            <uri>meshes/drive.dae</uri>
          </mesh>
        </geometry>
      </visual>
    </link>
    <joint name="RH_HAA" type="revolute">
      <child>RH_HIP</child>
      <parent>base</parent>
      <axis>
        <xyz>-1 0 0</xyz>
        <limit>
          <lower>-0.49</lower>
          <upper>0.72</upper>
          <effort>80</effort>
          <velocity>7.5</velocity>
        </limit>
        <dynamics>
          <damping>0</damping>
          <friction>0</friction>
          <spring_reference>0</spring_reference>
          <spring_stiffness>0</spring_stiffness>
        </dynamics>
        <use_parent_model_frame>0</use_parent_model_frame>
      </axis>
    </joint>
    <link name="RH_THIGH">
      <pose>-0.23387 -0.1220765 0 0 0 -1.5708</pose>
      <inertial>
        <pose>0.02002975 2.99e-05 -0.1597024 0 0 0</pose>
        <mass>3.071</mass>
        <inertia>
          <ixx>0.0295638</ixx>
          <ixy>4.42919e-05</ixy>
          <ixz>0.00414243</ixz>
          <iyy>0.029904</iyy>
          <iyz>9.448e-05</iyz>
          <izz>0.00486108</izz>
        </inertia>
      </inertial>
      <collision name="RH_THIGH_fixed_joint_lump__RH_thigh_fixed_collision">
        <pose>0.026 0 0 1.5708 0 1.5708</pose>
        <geometry>
          <cylinder>
            <length>0.052</length>
            <radius>0.04225</radius>
          </cylinder>
        </geometry>
      </collision>
      <collision name="RH_THIGH_fixed_joint_lump__RH_thigh_fixed_collision_1">
        <pose>0.0195 0 -0.0918541 0 0 1.5708</pose>
        <geometry>
          <box>
            <size>0.04875 0.039 0.18370755</size>
          </box>
        </geometry>
      </collision>
      <collision name="RH_THIGH_fixed_joint_lump__RH_KFE_collision_2">
        <pose>0.019695 0 -0.18525 0 1.5708 0</pose>
        <geometry>
          <cylinder>
            <length>0.091</length>
            <radius>0.0325</radius>
          </cylinder>
        </geometry>
      </collision>
      <visual name="RH_THIGH_fixed_joint_lump__RH_thigh_fixed_visual">
        <pose>0 0 0 0 0 -1.5708</pose>
        <geometry>
          <mesh>
            <scale>0.65 0.65 0.65</scale>
            <uri>meshes/thigh.dae</uri>
          </mesh>
        </geometry>
      </visual>
      <visual name="RH_THIGH_fixed_joint_lump__RH_KFE_visual_1">
        <pose>0.065195 0 -0.18525 0 0 0</pose>
        <geometry>
          <mesh>
            <scale>0.65 0.65 0.65</scale>
            <uri>meshes/drive.dae</uri>
          </mesh>
        </geometry>
      </visual>
    </link>
    <joint name="RH_HFE" type="revolute">
      <child>RH_THIGH</child>
      <parent>RH_HIP</parent>
      <axis>
        <xyz>-1 0 0</xyz>
        <limit>
          <lower>-9.42478</lower>
          <upper>9.42478</upper>
          <effort>80</effort>
          <velocity>7.5</velocity>
        </limit>
        <dynamics>
          <damping>0</damping>
          <friction>0</friction>
          <spring_reference>0</spring_reference>
          <spring_stiffness>0</spring_stiffness>
        </dynamics>
        <use_parent_model_frame>0</use_parent_model_frame>
      </axis>
    </joint>
    <link name="RH_SHANK">
      <pose>-0.23387 -0.1872715 -0.18525 0 0 -1.5708</pose>
      <inertial>
        <pose>0.0035503 -0.03981445 -0.052429 0 0 0</pose>
        <mass>0.58842</mass>
        <inertia>
          <ixx>0.0101611</ixx>
          <ixy>-5.35713e-05</ixy>
          <ixz>-2.26604e-05</ixz>
          <iyy>0.00881038</iyy>
          <iyz>-0.00181935</iyz>
          <izz>0.00154978</izz>
        </inertia>
      </inertial>
      <collision name="RH_SHANK_fixed_joint_lump__RH_shank_fixed_collision">
        <pose>0.013 0 0 1.5708 0 1.5708</pose>
        <geometry>
          <cylinder>
            <length>0.026</length>
            <radius>0.039</radius>
          </cylinder>
        </geometry>
      </collision>
      <collision name="RH_SHANK_fixed_joint_lump__RH_shank_fixed_collision_1">
        <pose>0.013 -0.03737435 0 1.5708 0 1.5708</pose>
        <geometry>
          <box>
            <size>0.0747487 0.043875 0.026</size>
          </box>
        </geometry>
      </collision>
      <collision name="RH_SHANK_fixed_joint_lump__RH_FOOT_collision_2">
        <pose>0.0084825 -0.0571675 -0.10984025 0 0 1.5708</pose>
        <geometry>
          <cylinder>
            <length>0.1836276</length>
            <radius>0.011375</radius>
          </cylinder>
        </geometry>
      </collision>
      <collision name="RH_SHANK_fixed_joint_lump__RH_FOOT_collision_3">
        <pose>0.0084825 -0.0571675 -0.2050555 0 0 1.5708</pose>
        <geometry>
          <sphere>
            <radius>0.0195</radius>
          </sphere>
        </geometry>
      </collision>
      <visual name="RH_SHANK_fixed_joint_lump__RH_shank_fixed_visual">
        <pose>0 0 0 0 0 -1.5708</pose>
        <geometry>
          <mesh>
            <scale>0.65 0.65 0.65</scale>
            <uri>meshes/shank_l.dae</uri>
          </mesh>
        </geometry>
      </visual>
      <visual name="RH_SHANK_fixed_joint_lump__RH_FOOT_visual_1">
        <pose>0.0084825 -0.0571675 -0.2196805 0 0 -2.35619</pose>
        <geometry>
          <mesh>
            <scale>0.65 0.65 0.65</scale>
            <uri>meshes/foot.dae</uri>
          </mesh>
        </geometry>
      </visual>
    </link>
    <joint name="RH_KFE" type="revolute">
      <child>RH_SHANK</child>
      <parent>RH_THIGH</parent>
      <axis>
        <xyz>-1 0 0</xyz>
        <limit>
          <lower>-9.42478</lower>
          <upper>9.42478</upper>
          <effort>80</effort>
          <velocity>7.5</velocity>
        </limit>
        <dynamics>
          <damping>0</damping>
          <friction>0</friction>
          <spring_reference>0</spring_reference>
          <spring_stiffness>0</spring_stiffness>
        </dynamics>
        <use_parent_model_frame>0</use_parent_model_frame>
      </axis>
    </joint>
  </model>
</sdf>
